Workbook
Name _?nsorteos_100: 'CG100'!$A$1:$G$509
Name _?nsorteos_20: 'CG20'!$A$1:$G$514
Name estadisticas: 'CG50'!$A$1:$G$509
Name quini6estadisticas: HIST!$A$1:$F$75

Sheet HIST
A1: QUINI 6
A2: QUINI 6 ESTADISTICAS
A3: QUINI 6 SORTEOS
A4: BRINCO RESULTADOS
A5: LOTO RESULTADOS
A6: QUINIELAS
A7: TELEKINO
A8: HOROSCOPO de HOY
A9: SIGNIFICADO DE LOS SUEÃ‘OS
A10: Quini 6 EstadÃ­sticas HistÃ³ricas
A11: EstadÃ­sticas del quini 6 desde los sorteos del 2008 hasta los actuales
A12: Ordenar Por: NÃºmero Cantidad salidas Fecha Ãºltima salida
A13: NÃºmero | B13: Cantidad de salidas | C13: DÃ­a Ãºltima salida
A14: 0 | B14: 1007 | C14: 46225
A15: 1 | B15: 1052 | C15: 46225
A16: 2 | B16: 1083 | C16: 46225
A17: 3 | B17: 964 | C17: 46219
A18: 4 | B18: 1025 | C18: 46222
A19: 5 | B19: 1004 | C19: 46225
A20: 6 | B20: 1067 | C20: 46225
A21: 7 | B21: 982 | C21: 46225
A22: 8 | B22: 1058 | C22: 46225
A23: 9 | B23: 1157 | C23: 46208
A24: 10 | B24: 1074 | C24: 46225
A25: 11 | B25: 996 | C25: 46215
... A59: 45 | B59: 1002 | C59: 46225
A60: Fijate si alguna vez salieron tus nÃºmeros en el Quini 6
A61: Ingresa los nÃºmeros
A64: Los sorteos especiales de navidad no son tenidos en cuenta para las estadÃ­sticas.
A65: Esto es solo para saber si los numeros fueron sorteados alguna vez, si lo que deseas es controlar tu boletaingresa aquÃ­
A66: Mejor estrategia para jugar al quini 6
A67: Como todos saben en el quini hay 46 bolillas las cuales, segÃºn la teorÃ­a, tienen exactamente la misma probabilidad de salir.
A68: Cuando se tira una moneda, hay dos posibilidades o que salga cara o que salga nÃºmero y cada una de esas posibilidades tiene la misma probabilidad (50 y 50 en este caso), debido a esto es de esperar que si realizamos un nÃºmero considerable de tiradas de la moneda saldrÃ¡n similares cantidad de veces cara y nÃºmero. Eso es mÃ¡s cierto a medida que se hacen mÃ¡s lanzamientos (pueden verificar ustedes mismos) o sea que mientras mÃ¡s veces tiremos la moneda mÃ¡s se emparejarÃ¡n las cantidades de veces que sale nÃºmero y cara.
A69: Para el caso del quini 6 se cumple lo mismo solo que las posibilidades no son dos sino 45. A medida que se van realizando mÃ¡s y mÃ¡s sorteos el nÃºmero de veces que sale cada nÃºmero se deberÃ­a ir emparejando.
A70: Por esto, si no tenemos ninguna mejor opciÃ³n, lo que podriamos hacer es jugar los nÃºmeros que hayan salido menos veces, ya que la cantidad de salidas tiende a emparejarse entre las 45 posibilidades.
A71: En la tabla de estadÃ­sticas de esta pÃ¡gina, pueden ordenar los nÃºmeros por cantidad de veces que salieron sorteados y asÃ­ intentar jugar los que hayan salido menos, no se hagan ilusiones que no es para nada la formula para ganar el quini 6. MÃ¡s bien tomenlo como una cÃ¡bala mÃ¡s o menos argumentada.
A72: MUCHA SUERTE!
A73: Jugar compulsivamente es perjudicial para la salud
... A75: Â© 2024 Quini 6 Resultados | Politica de Cookies | Resultados en tu WEB

Sheet CG100
A1: EspañaLoterías de España Reino UnidoLoterías de Reino Unido AlemaniaLoterías de Alemania Estados UnidosLoterías de Estados Unidos ItaliaLoterías de Italia BrasilLoterías de Brasil MexicoLoterías de Mexico ChileLoterías de Chile BélgicaLoterías de Bélgica ArgentinaLoterías de Argentina ColombiaLoterías de Colombia Costa RicaLoterías de Costa Rica PerúLoterías de Perú UruguayLoterías de Uruguay AustriaLoterías de Austria Costa De MarfilLoterías de Costa De Marfil CroaciaLoterías de Croacia FinlandiaLoterías de Finlandia HungríaLoterías de Hungría IslandiaLoterías de Islandia IrlandaLoterías de Irlanda KeniaLoterías de Kenia LetoniaLoterías de Letonia LuxemburgoLoterías de Luxemburgo MaltaLoterías de Malta MarruecosLoterías de Marruecos Países BajosLoterías de Países Bajos NigeriaLoterías de Nigeria NoruegaLoterías de Noruega PortugalLoterías de Portugal SerbiaLoterías de Serbia SudáfricaLoterías de Sudáfrica SuizaLoterías de Suiza UcraniaLoterías de Ucrania Emiratos ÁrabesLoterías de Emiratos árabes CanadáLoterías de Canadá AustraliaLoterías de Australia JapónLoterías de Japón FranciaLoterías de Francia PoloniaLoterías de Polonia EsloveniaLoterías de Eslovenia EslovaquiaLoterías de Eslovaquia DinamarcaLoterías de Dinamarca LituaniaLoterías de Lituania SueciaLoterías de Suecia EstoniaLoterías de Estonia República ChecaLoterías de República Checa
A2: Selecciona el país
A3: EspañaEspaña
A4: Reino UnidoReino Unido
A5: AlemaniaAlemania
A6: Estados UnidosEstados Unidos
A7: ItaliaItalia
A8: BrasilBrasil
A9: MexicoMexico
A10: ChileChile
A11: BélgicaBélgica
A12: ArgentinaArgentina
... A342: Bote de Megamillions
A343: 800
A344: millones de dólares
A345: Martes, 28 julio 2026
A346: JUGAR ONLINE
A347: Quini 6
A348: Comprobar
A349: Pronosticador
A350: Jugar
A351: Resultados
A352: Estadísticas
A353: Noticias
A354: más
A355: Quini 6 | B355: Comprobar | C355: Pronosticador | D355: Jugar | E355: Más
E356: Resultados | F356: Estadísticas | G356: Noticias
A357: Estadísticas de Quini 6
A359: Los sorteos de lotería como Quini 6 se suelen basar en la aleatoriedad de su resultado, siendo el azar el que determina la combinación ganadora. Esto hace que sea un juego justo, en el que no debe interferir ningún otro factor. Sin embargo, la suerte es caprichosa y en los sorteos suele haber números que aparecen más y otros menos. En las siguientes tabla se muestran estadísticas de los sorteos realizados en los últimos sorteos, con datos actualizados hasta el sorteo del día 22/07/2026.
A361: Número de sorteos:
A363: Apariciones
A365: Número | B365: Apariciones | C365: Promedio
A366: 0 | B366: 13 | C366: 2.17%
A367: 1 | B367: 10 | C367: 1.67%
A368: 2 | B368: 12 | C368: 2.00%
A369: 3 | B369: 9 | C369: 1.50%
A370: 4 | B370: 16 | C370: 2.67%
A371: 5 | B371: 16 | C371: 2.67%
A372: 6 | B372: 14 | C372: 2.33%
A373: 7 | B373: 15 | C373: 2.50%
...

Sheet CG50
A1: EspañaLoterías de España Reino UnidoLoterías de Reino Unido AlemaniaLoterías de Alemania Estados UnidosLoterías de Estados Unidos ItaliaLoterías de Italia BrasilLoterías de Brasil MexicoLoterías de Mexico ChileLoterías de Chile BélgicaLoterías de Bélgica ArgentinaLoterías de Argentina ColombiaLoterías de Colombia Costa RicaLoterías de Costa Rica PerúLoterías de Perú UruguayLoterías de Uruguay AustriaLoterías de Austria Costa De MarfilLoterías de Costa De Marfil CroaciaLoterías de Croacia FinlandiaLoterías de Finlandia HungríaLoterías de Hungría IslandiaLoterías de Islandia IrlandaLoterías de Irlanda KeniaLoterías de Kenia LetoniaLoterías de Letonia LuxemburgoLoterías de Luxemburgo MaltaLoterías de Malta MarruecosLoterías de Marruecos Países BajosLoterías de Países Bajos NigeriaLoterías de Nigeria NoruegaLoterías de Noruega PortugalLoterías de Portugal SerbiaLoterías de Serbia SudáfricaLoterías de Sudáfrica SuizaLoterías de Suiza UcraniaLoterías de Ucrania Emiratos ÁrabesLoterías de Emiratos árabes CanadáLoterías de Canadá AustraliaLoterías de Australia JapónLoterías de Japón FranciaLoterías de Francia PoloniaLoterías de Polonia EsloveniaLoterías de Eslovenia EslovaquiaLoterías de Eslovaquia DinamarcaLoterías de Dinamarca LituaniaLoterías de Lituania SueciaLoterías de Suecia EstoniaLoterías de Estonia República ChecaLoterías de República Checa
A2: Selecciona el país
A3: EspañaEspaña
A4: Reino UnidoReino Unido
A5: AlemaniaAlemania
A6: Estados UnidosEstados Unidos
A7: ItaliaItalia
A8: BrasilBrasil
A9: MexicoMexico
A10: ChileChile
A11: BélgicaBélgica
A12: ArgentinaArgentina
... A342: Bote de Megamillions
A343: 800
A344: millones de dólares
A345: Martes, 28 julio 2026
A346: JUGAR ONLINE
A347: Quini 6
A348: Comprobar
A349: Pronosticador
A350: Jugar
A351: Resultados
A352: Estadísticas
A353: Noticias
A354: más
A355: Quini 6 | B355: Comprobar | C355: Pronosticador | D355: Jugar | E355: Más
E356: Resultados | F356: Estadísticas | G356: Noticias
A357: Estadísticas de Quini 6
A359: Los sorteos de lotería como Quini 6 se suelen basar en la aleatoriedad de su resultado, siendo el azar el que determina la combinación ganadora. Esto hace que sea un juego justo, en el que no debe interferir ningún otro factor. Sin embargo, la suerte es caprichosa y en los sorteos suele haber números que aparecen más y otros menos. En las siguientes tabla se muestran estadísticas de los sorteos realizados en los últimos sorteos, con datos actualizados hasta el sorteo del día 22/07/2026.
A361: Número de sorteos:
A363: Apariciones
A365: Número | B365: Apariciones | C365: Promedio
A366: 0 | B366: 9 | C366: 3.00%
A367: 1 | B367: 7 | C367: 2.33%
A368: 2 | B368: 5 | C368: 1.67%
A369: 3 | B369: 5 | C369: 1.67%
A370: 4 | B370: 6 | C370: 2.00%
A371: 5 | B371: 8 | C371: 2.67%
A372: 6 | B372: 9 | C372: 3.00%
A373: 7 | B373: 10 | C373: 3.33%
...

Sheet CG20
A1: EspañaLoterías de España Reino UnidoLoterías de Reino Unido AlemaniaLoterías de Alemania Estados UnidosLoterías de Estados Unidos ItaliaLoterías de Italia BrasilLoterías de Brasil MexicoLoterías de Mexico ChileLoterías de Chile BélgicaLoterías de Bélgica ArgentinaLoterías de Argentina ColombiaLoterías de Colombia Costa RicaLoterías de Costa Rica PerúLoterías de Perú UruguayLoterías de Uruguay AustriaLoterías de Austria Costa De MarfilLoterías de Costa De Marfil CroaciaLoterías de Croacia FinlandiaLoterías de Finlandia HungríaLoterías de Hungría IslandiaLoterías de Islandia IrlandaLoterías de Irlanda KeniaLoterías de Kenia LetoniaLoterías de Letonia LuxemburgoLoterías de Luxemburgo MaltaLoterías de Malta MarruecosLoterías de Marruecos Países BajosLoterías de Países Bajos NigeriaLoterías de Nigeria NoruegaLoterías de Noruega PortugalLoterías de Portugal SerbiaLoterías de Serbia SudáfricaLoterías de Sudáfrica SuizaLoterías de Suiza UcraniaLoterías de Ucrania Emiratos ÁrabesLoterías de Emiratos árabes CanadáLoterías de Canadá AustraliaLoterías de Australia JapónLoterías de Japón FranciaLoterías de Francia PoloniaLoterías de Polonia EsloveniaLoterías de Eslovenia EslovaquiaLoterías de Eslovaquia DinamarcaLoterías de Dinamarca LituaniaLoterías de Lituania SueciaLoterías de Suecia EstoniaLoterías de Estonia República ChecaLoterías de República Checa
A2: Selecciona el país
A3: EspañaEspaña
A4: Reino UnidoReino Unido
A5: AlemaniaAlemania
A6: Estados UnidosEstados Unidos
A7: ItaliaItalia
A8: BrasilBrasil
A9: MexicoMexico
A10: ChileChile
A11: BélgicaBélgica
A12: ArgentinaArgentina
... A340: Bote de Megamillions
A341: 800
A342: millones de dólares
A343: Martes, 28 julio 2026
A344: JUGAR ONLINE
A345: Siguiente sorteo:
A346: 4.294.967.2954.295,0M$
A347: Jugar
A348: Quini 6
A349: Comprobar
A350: Pronosticador
A351: Jugar
A352: Resultados
A353: Estadísticas
... A355: más
A356: Quini 6 | B356: Comprobar | C356: Pronosticador | D356: Jugar | E356: Más
E357: Resultados | F357: Estadísticas | G357: Noticias
A358: Estadísticas de Quini 6
A360: Los sorteos de lotería como Quini 6 se suelen basar en la aleatoriedad de su resultado, siendo el azar el que determina la combinación ganadora. Esto hace que sea un juego justo, en el que no debe interferir ningún otro factor. Sin embargo, la suerte es caprichosa y en los sorteos suele haber números que aparecen más y otros menos. En las siguientes tabla se muestran estadísticas de los sorteos realizados en los últimos sorteos, con datos actualizados hasta el sorteo del día 26/07/2026.
A362: Número de sorteos:
A364: Apariciones
A366: Número | B366: Apariciones | C366: Promedio
A367: 0 | B367: 3 | C367: 2.50%
A368: 1 | B368: 4 | C368: 3.33%
A369: 2 | B369: 1 | C369: 0.83%
A370: 3 | B370: 2 | C370: 1.67%
A371: 4 | B371: 1 | C371: 0.83%
A372: 5 | B372: 5 | C372: 4.17%
...

Sheet Stats
A1: numero | B1: ap20 | C1: au20 | D1: sc20 | E1: ap50 | F1: au50 | G1: sc50 | H1: ap100 | I1: au100 | J1: sc100 | K1: hist_ap | L1: ult_salida | M1: atraso | N1: grupo | O1: categoria | Q1: Freq Alta | R1: =_xlfn.PERCENTILE.INC(K2:K47,0.75) -> 1093.75
A2: 0 | B2: =+VLOOKUP($A2,'CG20'!$A$364:$B$440,2,FALSE) -> 3 | C2: =+VLOOKUP($A2,'CG20'!$A$436:$B$500,2,FALSE) -> 17 | D2: =+B2*0.6/20+C2*0.4/20 -> 0.43 | E2: =+VLOOKUP($A2,'CG50'!$A$364:$B$440,2,FALSE) -> 9 | F2: =+VLOOKUP($A2,'CG50'!$A$436:$B$500,2,FALSE) -> 41 | G2: =+E2*0.6/50+F2*0.4/50 -> 0.436 | H2: =+VLOOKUP($A2,'CG100'!$A$364:$B$440,2,FALSE) -> 13 | I2: =+VLOOKUP($A2,'CG100'!$A$436:$B$500,2,FALSE) -> 87 | J2: =+H2*0.6/100+I2*0.4/100 -> 0.426 | K2: =+VLOOKUP($A2,HIST!$A:$C,2,FALSE) -> 1007 | L2: =+VLOOKUP($A2,HIST!$A:$C,3,FALSE) -> 46225 | M2: =IF(L2="","",TODAY()-L2) -> 5 | N2: =IF(K2="","",IF(K2>=R1,"Caliente",IF(K2<=R2,"Frio","Medio"))) -> Medio | O2: =IF(N2="","",IF(M2>=R3,N2&" atrasado",N2&" reciente")) -> Medio reciente | Q2: Freq Baja | R2: =_xlfn.PERCENTILE.INC(K2:K47,0.25) -> 990.5
A3: 1 | B3: =+VLOOKUP($A3,'CG20'!$A$364:$B$440,2,FALSE) -> 4 | C3: =+VLOOKUP($A3,'CG20'!$A$436:$B$500,2,FALSE) -> 16 | D3: =+B3*0.6/20+C3*0.4/20 -> 0.44 | E3: =+VLOOKUP($A3,'CG50'!$A$364:$B$440,2,FALSE) -> 7 | F3: =+VLOOKUP($A3,'CG50'!$A$436:$B$500,2,FALSE) -> 43 | G3: =+E3*0.6/50+F3*0.4/50 -> 0.428 | H3: =+VLOOKUP($A3,'CG100'!$A$364:$B$440,2,FALSE) -> 10 | I3: =+VLOOKUP($A3,'CG100'!$A$436:$B$500,2,FALSE) -> 90 | J3: =+H3*0.6/100+I3*0.4/100 -> 0.42 | K3: =+VLOOKUP(A3,HIST!$A:$C,2,FALSE) -> 1052 | L3: =+VLOOKUP($A3,HIST!$A:$C,3,FALSE) -> 46225 | M3: =IF(L3="","",TODAY()-L3) -> 5 | N3: =IF(K3="","",IF(K3>=R1,"Caliente",IF(K3<=R2,"Frio","Medio"))) -> Medio | O3: =IF(N3="","",IF(M3>=R3,N3&" atrasado",N3&" reciente")) -> Medio reciente | Q3: Atraso Alto | R3: =_xlfn.PERCENTILE.INC(M2:M47,0.8) -> 11
A4: 2 | B4: =+VLOOKUP($A4,'CG20'!$A$364:$B$440,2,FALSE) -> 1 | C4: =+VLOOKUP($A4,'CG20'!$A$436:$B$500,2,FALSE) -> 19 | D4: =+B4*0.6/20+C4*0.4/20 -> 0.41 | E4: =+VLOOKUP($A4,'CG50'!$A$364:$B$440,2,FALSE) -> 5 | F4: =+VLOOKUP($A4,'CG50'!$A$436:$B$500,2,FALSE) -> 45 | G4: =+E4*0.6/50+F4*0.4/50 -> 0.42 | H4: =+VLOOKUP($A4,'CG100'!$A$364:$B$440,2,FALSE) -> 12 | I4: =+VLOOKUP($A4,'CG100'!$A$436:$B$500,2,FALSE) -> 88 | J4: =+H4*0.6/100+I4*0.4/100 -> 0.424 | K4: =+VLOOKUP(A4,HIST!$A:$C,2,FALSE) -> 1083 | L4: =+VLOOKUP($A4,HIST!$A:$C,3,FALSE) -> 46225 | M4: =IF(L4="","",TODAY()-L4) -> 5 | N4: =IF(K4="","",IF(K4>=R1,"Caliente",IF(K4<=R2,"Frio","Medio"))) -> Medio | O4: =IF(N4="","",IF(M4>=R3,N4&" atrasado",N4&" reciente")) -> Medio reciente
A5: 3 | B5: =+VLOOKUP($A5,'CG20'!$A$364:$B$440,2,FALSE) -> 2 | C5: =+VLOOKUP($A5,'CG20'!$A$436:$B$500,2,FALSE) -> 18 | D5: =+B5*0.6/20+C5*0.4/20 -> 0.42 | E5: =+VLOOKUP($A5,'CG50'!$A$364:$B$440,2,FALSE) -> 5 | F5: =+VLOOKUP($A5,'CG50'!$A$436:$B$500,2,FALSE) -> 45 | G5: =+E5*0.6/50+F5*0.4/50 -> 0.42 | H5: =+VLOOKUP($A5,'CG100'!$A$364:$B$440,2,FALSE) -> 9 | I5: =+VLOOKUP($A5,'CG100'!$A$436:$B$500,2,FALSE) -> 91 | J5: =+H5*0.6/100+I5*0.4/100 -> 0.418 | K5: =+VLOOKUP(A5,HIST!$A:$C,2,FALSE) -> 964 | L5: =+VLOOKUP($A5,HIST!$A:$C,3,FALSE) -> 46219 | M5: =IF(L5="","",TODAY()-L5) -> 11 | N5: =IF(K5="","",IF(K5>=R1,"Caliente",IF(K5<=R2,"Frio","Medio"))) -> Frio | O5: =IF(N5="","",IF(M5>=R3,N5&" atrasado",N5&" reciente")) -> Frio atrasado
A6: 4 | B6: =+VLOOKUP($A6,'CG20'!$A$364:$B$440,2,FALSE) -> 1 | C6: =+VLOOKUP($A6,'CG20'!$A$436:$B$500,2,FALSE) -> 19 | D6: =+B6*0.6/20+C6*0.4/20 -> 0.41 | E6: =+VLOOKUP($A6,'CG50'!$A$364:$B$440,2,FALSE) -> 6 | F6: =+VLOOKUP($A6,'CG50'!$A$436:$B$500,2,FALSE) -> 44 | G6: =+E6*0.6/50+F6*0.4/50 -> 0.424 | H6: =+VLOOKUP($A6,'CG100'!$A$364:$B$440,2,FALSE) -> 16 | I6: =+VLOOKUP($A6,'CG100'!$A$436:$B$500,2,FALSE) -> 84 | J6: =+H6*0.6/100+I6*0.4/100 -> 0.432 | K6: =+VLOOKUP(A6,HIST!$A:$C,2,FALSE) -> 1025 | L6: =+VLOOKUP($A6,HIST!$A:$C,3,FALSE) -> 46222 | M6: =IF(L6="","",TODAY()-L6) -> 8 | N6: =IF(K6="","",IF(K6>=R1,"Caliente",IF(K6<=R2,"Frio","Medio"))) -> Medio | O6: =IF(N6="","",IF(M6>=R3,N6&" atrasado",N6&" reciente")) -> Medio reciente
A7: 5 | B7: =+VLOOKUP($A7,'CG20'!$A$364:$B$440,2,FALSE) -> 5 | C7: =+VLOOKUP($A7,'CG20'!$A$436:$B$500,2,FALSE) -> 15 | D7: =+B7*0.6/20+C7*0.4/20 -> 0.45 | E7: =+VLOOKUP($A7,'CG50'!$A$364:$B$440,2,FALSE) -> 8 | F7: =+VLOOKUP($A7,'CG50'!$A$436:$B$500,2,FALSE) -> 42 | G7: =+E7*0.6/50+F7*0.4/50 -> 0.432 | H7: =+VLOOKUP($A7,'CG100'!$A$364:$B$440,2,FALSE) -> 16 | I7: =+VLOOKUP($A7,'CG100'!$A$436:$B$500,2,FALSE) -> 84 | J7: =+H7*0.6/100+I7*0.4/100 -> 0.432 | K7: =+VLOOKUP(A7,HIST!$A:$C,2,FALSE) -> 1004 | L7: =+VLOOKUP($A7,HIST!$A:$C,3,FALSE) -> 46225 | M7: =IF(L7="","",TODAY()-L7) -> 5 | N7: =IF(K7="","",IF(K7>=R1,"Caliente",IF(K7<=R2,"Frio","Medio"))) -> Medio | O7: =IF(N7="","",IF(M7>=R3,N7&" atrasado",N7&" reciente")) -> Medio reciente
A8: 6 | B8: =+VLOOKUP($A8,'CG20'!$A$364:$B$440,2,FALSE) -> 1 | C8: =+VLOOKUP($A8,'CG20'!$A$436:$B$500,2,FALSE) -> 19 | D8: =+B8*0.6/20+C8*0.4/20 -> 0.41 | E8: =+VLOOKUP($A8,'CG50'!$A$364:$B$440,2,FALSE) -> 9 | F8: =+VLOOKUP($A8,'CG50'!$A$436:$B$500,2,FALSE) -> 41 | G8: =+E8*0.6/50+F8*0.4/50 -> 0.436 | H8: =+VLOOKUP($A8,'CG100'!$A$364:$B$440,2,FALSE) -> 14 | I8: =+VLOOKUP($A8,'CG100'!$A$436:$B$500,2,FALSE) -> 86 | J8: =+H8*0.6/100+I8*0.4/100 -> 0.428 | K8: =+VLOOKUP(A8,HIST!$A:$C,2,FALSE) -> 1067 | L8: =+VLOOKUP($A8,HIST!$A:$C,3,FALSE) -> 46225 | M8: =IF(L8="","",TODAY()-L8) -> 5 | N8: =IF(K8="","",IF(K8>=R1,"Caliente",IF(K8<=R2,"Frio","Medio"))) -> Medio | O8: =IF(N8="","",IF(M8>=R3,N8&" atrasado",N8&" reciente")) -> Medio reciente
A9: 7 | B9: =+VLOOKUP($A9,'CG20'!$A$364:$B$440,2,FALSE) -> 5 | C9: =+VLOOKUP($A9,'CG20'!$A$436:$B$500,2,FALSE) -> 15 | D9: =+B9*0.6/20+C9*0.4/20 -> 0.45 | E9: =+VLOOKUP($A9,'CG50'!$A$364:$B$440,2,FALSE) -> 10 | F9: =+VLOOKUP($A9,'CG50'!$A$436:$B$500,2,FALSE) -> 40 | G9: =+E9*0.6/50+F9*0.4/50 -> 0.44 | H9: =+VLOOKUP($A9,'CG100'!$A$364:$B$440,2,FALSE) -> 15 | I9: =+VLOOKUP($A9,'CG100'!$A$436:$B$500,2,FALSE) -> 85 | J9: =+H9*0.6/100+I9*0.4/100 -> 0.43 | K9: =+VLOOKUP(A9,HIST!$A:$C,2,FALSE) -> 982 | L9: =+VLOOKUP($A9,HIST!$A:$C,3,FALSE) -> 46225 | M9: =IF(L9="","",TODAY()-L9) -> 5 | N9: =IF(K9="","",IF(K9>=R1,"Caliente",IF(K9<=R2,"Frio","Medio"))) -> Frio | O9: =IF(N9="","",IF(M9>=R3,N9&" atrasado",N9&" reciente")) -> Frio reciente
A10: 8 | B10: =+VLOOKUP($A10,'CG20'!$A$364:$B$440,2,FALSE) -> 6 | C10: =+VLOOKUP($A10,'CG20'!$A$436:$B$500,2,FALSE) -> 14 | D10: =+B10*0.6/20+C10*0.4/20 -> 0.46 | E10: =+VLOOKUP($A10,'CG50'!$A$364:$B$440,2,FALSE) -> 9 | F10: =+VLOOKUP($A10,'CG50'!$A$436:$B$500,2,FALSE) -> 41 | G10: =+E10*0.6/50+F10*0.4/50 -> 0.436 | H10: =+VLOOKUP($A10,'CG100'!$A$364:$B$440,2,FALSE) -> 16 | I10: =+VLOOKUP($A10,'CG100'!$A$436:$B$500,2,FALSE) -> 84 | J10: =+H10*0.6/100+I10*0.4/100 -> 0.432 | K10: =+VLOOKUP(A10,HIST!$A:$C,2,FALSE) -> 1058 | L10: =+VLOOKUP($A10,HIST!$A:$C,3,FALSE) -> 46225 | M10: =IF(L10="","",TODAY()-L10) -> 5 | N10: =IF(K10="","",IF(K10>=R1,"Caliente",IF(K10<=R2,"Frio","Medio"))) -> Medio | O10: =IF(N10="","",IF(M10>=R3,N10&" atrasado",N10&" reciente")) -> Medio reciente
A11: 9 | B11: =+VLOOKUP($A11,'CG20'!$A$364:$B$440,2,FALSE) -> 1 | C11: =+VLOOKUP($A11,'CG20'!$A$436:$B$500,2,FALSE) -> 19 | D11: =+B11*0.6/20+C11*0.4/20 -> 0.41 | E11: =+VLOOKUP($A11,'CG50'!$A$364:$B$440,2,FALSE) -> 6 | F11: =+VLOOKUP($A11,'CG50'!$A$436:$B$500,2,FALSE) -> 44 | G11: =+E11*0.6/50+F11*0.4/50 -> 0.424 | H11: =+VLOOKUP($A11,'CG100'!$A$364:$B$440,2,FALSE) -> 16 | I11: =+VLOOKUP($A11,'CG100'!$A$436:$B$500,2,FALSE) -> 84 | J11: =+H11*0.6/100+I11*0.4/100 -> 0.432 | K11: =+VLOOKUP(A11,HIST!$A:$C,2,FALSE) -> 1157 | L11: =+VLOOKUP($A11,HIST!$A:$C,3,FALSE) -> 46208 | M11: =IF(L11="","",TODAY()-L11) -> 22 | N11: =IF(K11="","",IF(K11>=R1,"Caliente",IF(K11<=R2,"Frio","Medio"))) -> Caliente | O11: =IF(N11="","",IF(M11>=R3,N11&" atrasado",N11&" reciente")) -> Caliente atrasado
A12: 10 | B12: =+VLOOKUP($A12,'CG20'!$A$364:$B$440,2,FALSE) -> 4 | C12: =+VLOOKUP($A12,'CG20'!$A$436:$B$500,2,FALSE) -> 16 | D12: =+B12*0.6/20+C12*0.4/20 -> 0.44 | E12: =+VLOOKUP($A12,'CG50'!$A$364:$B$440,2,FALSE) -> 10 | F12: =+VLOOKUP($A12,'CG50'!$A$436:$B$500,2,FALSE) -> 40 | G12: =+E12*0.6/50+F12*0.4/50 -> 0.44 | H12: =+VLOOKUP($A12,'CG100'!$A$364:$B$440,2,FALSE) -> 14 | I12: =+VLOOKUP($A12,'CG100'!$A$436:$B$500,2,FALSE) -> 86 | J12: =+H12*0.6/100+I12*0.4/100 -> 0.428 | K12: =+VLOOKUP(A12,HIST!$A:$C,2,FALSE) -> 1074 | L12: =+VLOOKUP($A12,HIST!$A:$C,3,FALSE) -> 46225 | M12: =IF(L12="","",TODAY()-L12) -> 5 | N12: =IF(K12="","",IF(K12>=R1,"Caliente",IF(K12<=R2,"Frio","Medio"))) -> Medio | O12: =IF(N12="","",IF(M12>=R3,N12&" atrasado",N12&" reciente")) -> Medio reciente
A13: 11 | B13: =+VLOOKUP($A13,'CG20'!$A$364:$B$440,2,FALSE) -> 0 | C13: =+VLOOKUP($A13,'CG20'!$A$436:$B$500,2,FALSE) -> 20 | D13: =+B13*0.6/20+C13*0.4/20 -> 0.4 | E13: =+VLOOKUP($A13,'CG50'!$A$364:$B$440,2,FALSE) -> 1 | F13: =+VLOOKUP($A13,'CG50'!$A$436:$B$500,2,FALSE) -> 49 | G13: =+E13*0.6/50+F13*0.4/50 -> 0.404 | H13: =+VLOOKUP($A13,'CG100'!$A$364:$B$440,2,FALSE) -> 5 | I13: =+VLOOKUP($A13,'CG100'!$A$436:$B$500,2,FALSE) -> 95 | J13: =+H13*0.6/100+I13*0.4/100 -> 0.41 | K13: =+VLOOKUP(A13,HIST!$A:$C,2,FALSE) -> 996 | L13: =+VLOOKUP($A13,HIST!$A:$C,3,FALSE) -> 46215 | M13: =IF(L13="","",TODAY()-L13) -> 15 | N13: =IF(K13="","",IF(K13>=R1,"Caliente",IF(K13<=R2,"Frio","Medio"))) -> Medio | O13: =IF(N13="","",IF(M13>=R3,N13&" atrasado",N13&" reciente")) -> Medio atrasado
A14: 12 | B14: =+VLOOKUP($A14,'CG20'!$A$364:$B$440,2,FALSE) -> 3 | C14: =+VLOOKUP($A14,'CG20'!$A$436:$B$500,2,FALSE) -> 17 | D14: =+B14*0.6/20+C14*0.4/20 -> 0.43 | E14: =+VLOOKUP($A14,'CG50'!$A$364:$B$440,2,FALSE) -> 9 | F14: =+VLOOKUP($A14,'CG50'!$A$436:$B$500,2,FALSE) -> 41 | G14: =+E14*0.6/50+F14*0.4/50 -> 0.436 | H14: =+VLOOKUP($A14,'CG100'!$A$364:$B$440,2,FALSE) -> 17 | I14: =+VLOOKUP($A14,'CG100'!$A$436:$B$500,2,FALSE) -> 83 | J14: =+H14*0.6/100+I14*0.4/100 -> 0.434 | K14: =+VLOOKUP(A14,HIST!$A:$C,2,FALSE) -> 990 | L14: =+VLOOKUP($A14,HIST!$A:$C,3,FALSE) -> 46201 | M14: =IF(L14="","",TODAY()-L14) -> 29 | N14: =IF(K14="","",IF(K14>=R1,"Caliente",IF(K14<=R2,"Frio","Medio"))) -> Frio | O14: =IF(N14="","",IF(M14>=R3,N14&" atrasado",N14&" reciente")) -> Frio atrasado
A15: 13 | B15: =+VLOOKUP($A15,'CG20'!$A$364:$B$440,2,FALSE) -> 1 | C15: =+VLOOKUP($A15,'CG20'!$A$436:$B$500,2,FALSE) -> 19 | D15: =+B15*0.6/20+C15*0.4/20 -> 0.41 | E15: =+VLOOKUP($A15,'CG50'!$A$364:$B$440,2,FALSE) -> 6 | F15: =+VLOOKUP($A15,'CG50'!$A$436:$B$500,2,FALSE) -> 44 | G15: =+E15*0.6/50+F15*0.4/50 -> 0.424 | H15: =+VLOOKUP($A15,'CG100'!$A$364:$B$440,2,FALSE) -> 8 | I15: =+VLOOKUP($A15,'CG100'!$A$436:$B$500,2,FALSE) -> 92 | J15: =+H15*0.6/100+I15*0.4/100 -> 0.416 | K15: =+VLOOKUP(A15,HIST!$A:$C,2,FALSE) -> 974 | L15: =+VLOOKUP($A15,HIST!$A:$C,3,FALSE) -> 46187 | M15: =IF(L15="","",TODAY()-L15) -> 43 | N15: =IF(K15="","",IF(K15>=R1,"Caliente",IF(K15<=R2,"Frio","Medio"))) -> Frio | O15: =IF(N15="","",IF(M15>=R3,N15&" atrasado",N15&" reciente")) -> Frio atrasado
A16: 14 | B16: =+VLOOKUP($A16,'CG20'!$A$364:$B$440,2,FALSE) -> 0 | C16: =+VLOOKUP($A16,'CG20'!$A$436:$B$500,2,FALSE) -> 20 | D16: =+B16*0.6/20+C16*0.4/20 -> 0.4 | E16: =+VLOOKUP($A16,'CG50'!$A$364:$B$440,2,FALSE) -> 2 | F16: =+VLOOKUP($A16,'CG50'!$A$436:$B$500,2,FALSE) -> 48 | G16: =+E16*0.6/50+F16*0.4/50 -> 0.408 | H16: =+VLOOKUP($A16,'CG100'!$A$364:$B$440,2,FALSE) -> 13 | I16: =+VLOOKUP($A16,'CG100'!$A$436:$B$500,2,FALSE) -> 87 | J16: =+H16*0.6/100+I16*0.4/100 -> 0.426 | K16: =+VLOOKUP(A16,HIST!$A:$C,2,FALSE) -> 979 | L16: =+VLOOKUP($A16,HIST!$A:$C,3,FALSE) -> 46222 | M16: =IF(L16="","",TODAY()-L16) -> 8 | N16: =IF(K16="","",IF(K16>=R1,"Caliente",IF(K16<=R2,"Frio","Medio"))) -> Frio | O16: =IF(N16="","",IF(M16>=R3,N16&" atrasado",N16&" reciente")) -> Frio reciente
A17: 15 | B17: =+VLOOKUP($A17,'CG20'!$A$364:$B$440,2,FALSE) -> 2 | C17: =+VLOOKUP($A17,'CG20'!$A$436:$B$500,2,FALSE) -> 18 | D17: =+B17*0.6/20+C17*0.4/20 -> 0.42 | E17: =+VLOOKUP($A17,'CG50'!$A$364:$B$440,2,FALSE) -> 8 | F17: =+VLOOKUP($A17,'CG50'!$A$436:$B$500,2,FALSE) -> 42 | G17: =+E17*0.6/50+F17*0.4/50 -> 0.432 | H17: =+VLOOKUP($A17,'CG100'!$A$364:$B$440,2,FALSE) -> 11 | I17: =+VLOOKUP($A17,'CG100'!$A$436:$B$500,2,FALSE) -> 89 | J17: =+H17*0.6/100+I17*0.4/100 -> 0.422 | K17: =+VLOOKUP(A17,HIST!$A:$C,2,FALSE) -> 1127 | L17: =+VLOOKUP($A17,HIST!$A:$C,3,FALSE) -> 46211 | M17: =IF(L17="","",TODAY()-L17) -> 19 | N17: =IF(K17="","",IF(K17>=R1,"Caliente",IF(K17<=R2,"Frio","Medio"))) -> Caliente | O17: =IF(N17="","",IF(M17>=R3,N17&" atrasado",N17&" reciente")) -> Caliente atrasado
A18: 16 | B18: =+VLOOKUP($A18,'CG20'!$A$364:$B$440,2,FALSE) -> 3 | C18: =+VLOOKUP($A18,'CG20'!$A$436:$B$500,2,FALSE) -> 17 | D18: =+B18*0.6/20+C18*0.4/20 -> 0.43 | E18: =+VLOOKUP($A18,'CG50'!$A$364:$B$440,2,FALSE) -> 6 | F18: =+VLOOKUP($A18,'CG50'!$A$436:$B$500,2,FALSE) -> 44 | G18: =+E18*0.6/50+F18*0.4/50 -> 0.424 | H18: =+VLOOKUP($A18,'CG100'!$A$364:$B$440,2,FALSE) -> 15 | I18: =+VLOOKUP($A18,'CG100'!$A$436:$B$500,2,FALSE) -> 85 | J18: =+H18*0.6/100+I18*0.4/100 -> 0.43 | K18: =+VLOOKUP(A18,HIST!$A:$C,2,FALSE) -> 1078 | L18: =+VLOOKUP($A18,HIST!$A:$C,3,FALSE) -> 46219 | M18: =IF(L18="","",TODAY()-L18) -> 11 | N18: =IF(K18="","",IF(K18>=R1,"Caliente",IF(K18<=R2,"Frio","Medio"))) -> Medio | O18: =IF(N18="","",IF(M18>=R3,N18&" atrasado",N18&" reciente")) -> Medio atrasado
A19: 17 | B19: =+VLOOKUP($A19,'CG20'!$A$364:$B$440,2,FALSE) -> 3 | C19: =+VLOOKUP($A19,'CG20'!$A$436:$B$500,2,FALSE) -> 17 | D19: =+B19*0.6/20+C19*0.4/20 -> 0.43 | E19: =+VLOOKUP($A19,'CG50'!$A$364:$B$440,2,FALSE) -> 6 | F19: =+VLOOKUP($A19,'CG50'!$A$436:$B$500,2,FALSE) -> 44 | G19: =+E19*0.6/50+F19*0.4/50 -> 0.424 | H19: =+VLOOKUP($A19,'CG100'!$A$364:$B$440,2,FALSE) -> 14 | I19: =+VLOOKUP($A19,'CG100'!$A$436:$B$500,2,FALSE) -> 86 | J19: =+H19*0.6/100+I19*0.4/100 -> 0.428 | K19: =+VLOOKUP(A19,HIST!$A:$C,2,FALSE) -> 998 | L19: =+VLOOKUP($A19,HIST!$A:$C,3,FALSE) -> 46222 | M19: =IF(L19="","",TODAY()-L19) -> 8 | N19: =IF(K19="","",IF(K19>=R1,"Caliente",IF(K19<=R2,"Frio","Medio"))) -> Medio | O19: =IF(N19="","",IF(M19>=R3,N19&" atrasado",N19&" reciente")) -> Medio reciente
A20: 18 | B20: =+VLOOKUP($A20,'CG20'!$A$364:$B$440,2,FALSE) -> 2 | C20: =+VLOOKUP($A20,'CG20'!$A$436:$B$500,2,FALSE) -> 18 | D20: =+B20*0.6/20+C20*0.4/20 -> 0.42 | E20: =+VLOOKUP($A20,'CG50'!$A$364:$B$440,2,FALSE) -> 11 | F20: =+VLOOKUP($A20,'CG50'!$A$436:$B$500,2,FALSE) -> 39 | G20: =+E20*0.6/50+F20*0.4/50 -> 0.444 | H20: =+VLOOKUP($A20,'CG100'!$A$364:$B$440,2,FALSE) -> 20 | I20: =+VLOOKUP($A20,'CG100'!$A$436:$B$500,2,FALSE) -> 80 | J20: =+H20*0.6/100+I20*0.4/100 -> 0.44 | K20: =+VLOOKUP(A20,HIST!$A:$C,2,FALSE) -> 972 | L20: =+VLOOKUP($A20,HIST!$A:$C,3,FALSE) -> 46225 | M20: =IF(L20="","",TODAY()-L20) -> 5 | N20: =IF(K20="","",IF(K20>=R1,"Caliente",IF(K20<=R2,"Frio","Medio"))) -> Frio | O20: =IF(N20="","",IF(M20>=R3,N20&" atrasado",N20&" reciente")) -> Frio reciente
A21: 19 | B21: =+VLOOKUP($A21,'CG20'!$A$364:$B$440,2,FALSE) -> 2 | C21: =+VLOOKUP($A21,'CG20'!$A$436:$B$500,2,FALSE) -> 18 | D21: =+B21*0.6/20+C21*0.4/20 -> 0.42 | E21: =+VLOOKUP($A21,'CG50'!$A$364:$B$440,2,FALSE) -> 5 | F21: =+VLOOKUP($A21,'CG50'!$A$436:$B$500,2,FALSE) -> 45 | G21: =+E21*0.6/50+F21*0.4/50 -> 0.42 | H21: =+VLOOKUP($A21,'CG100'!$A$364:$B$440,2,FALSE) -> 10 | I21: =+VLOOKUP($A21,'CG100'!$A$436:$B$500,2,FALSE) -> 90 | J21: =+H21*0.6/100+I21*0.4/100 -> 0.42 | K21: =+VLOOKUP(A21,HIST!$A:$C,2,FALSE) -> 1215 | L21: =+VLOOKUP($A21,HIST!$A:$C,3,FALSE) -> 46222 | M21: =IF(L21="","",TODAY()-L21) -> 8 | N21: =IF(K21="","",IF(K21>=R1,"Caliente",IF(K21<=R2,"Frio","Medio"))) -> Caliente | O21: =IF(N21="","",IF(M21>=R3,N21&" atrasado",N21&" reciente")) -> Caliente reciente
A22: 20 | B22: =+VLOOKUP($A22,'CG20'!$A$364:$B$440,2,FALSE) -> 1 | C22: =+VLOOKUP($A22,'CG20'!$A$436:$B$500,2,FALSE) -> 19 | D22: =+B22*0.6/20+C22*0.4/20 -> 0.41 | E22: =+VLOOKUP($A22,'CG50'!$A$364:$B$440,2,FALSE) -> 10 | F22: =+VLOOKUP($A22,'CG50'!$A$436:$B$500,2,FALSE) -> 40 | G22: =+E22*0.6/50+F22*0.4/50 -> 0.44 | H22: =+VLOOKUP($A22,'CG100'!$A$364:$B$440,2,FALSE) -> 14 | I22: =+VLOOKUP($A22,'CG100'!$A$436:$B$500,2,FALSE) -> 86 | J22: =+H22*0.6/100+I22*0.4/100 -> 0.428 | K22: =+VLOOKUP(A22,HIST!$A:$C,2,FALSE) -> 1119 | L22: =+VLOOKUP($A22,HIST!$A:$C,3,FALSE) -> 46225 | M22: =IF(L22="","",TODAY()-L22) -> 5 | N22: =IF(K22="","",IF(K22>=R1,"Caliente",IF(K22<=R2,"Frio","Medio"))) -> Caliente | O22: =IF(N22="","",IF(M22>=R3,N22&" atrasado",N22&" reciente")) -> Caliente reciente
A23: 21 | B23: =+VLOOKUP($A23,'CG20'!$A$364:$B$440,2,FALSE) -> 3 | C23: =+VLOOKUP($A23,'CG20'!$A$436:$B$500,2,FALSE) -> 17 | D23: =+B23*0.6/20+C23*0.4/20 -> 0.43 | E23: =+VLOOKUP($A23,'CG50'!$A$364:$B$440,2,FALSE) -> 4 | F23: =+VLOOKUP($A23,'CG50'!$A$436:$B$500,2,FALSE) -> 46 | G23: =+E23*0.6/50+F23*0.4/50 -> 0.416 | H23: =+VLOOKUP($A23,'CG100'!$A$364:$B$440,2,FALSE) -> 15 | I23: =+VLOOKUP($A23,'CG100'!$A$436:$B$500,2,FALSE) -> 85 | J23: =+H23*0.6/100+I23*0.4/100 -> 0.43 | K23: =+VLOOKUP(A23,HIST!$A:$C,2,FALSE) -> 1002 | L23: =+VLOOKUP($A23,HIST!$A:$C,3,FALSE) -> 46222 | M23: =IF(L23="","",TODAY()-L23) -> 8 | N23: =IF(K23="","",IF(K23>=R1,"Caliente",IF(K23<=R2,"Frio","Medio"))) -> Medio | O23: =IF(N23="","",IF(M23>=R3,N23&" atrasado",N23&" reciente")) -> Medio reciente
A24: 22 | B24: =+VLOOKUP($A24,'CG20'!$A$364:$B$440,2,FALSE) -> 1 | C24: =+VLOOKUP($A24,'CG20'!$A$436:$B$500,2,FALSE) -> 19 | D24: =+B24*0.6/20+C24*0.4/20 -> 0.41 | E24: =+VLOOKUP($A24,'CG50'!$A$364:$B$440,2,FALSE) -> 3 | F24: =+VLOOKUP($A24,'CG50'!$A$436:$B$500,2,FALSE) -> 47 | G24: =+E24*0.6/50+F24*0.4/50 -> 0.412 | H24: =+VLOOKUP($A24,'CG100'!$A$364:$B$440,2,FALSE) -> 9 | I24: =+VLOOKUP($A24,'CG100'!$A$436:$B$500,2,FALSE) -> 91 | J24: =+H24*0.6/100+I24*0.4/100 -> 0.418 | K24: =+VLOOKUP(A24,HIST!$A:$C,2,FALSE) -> 1136 | L24: =+VLOOKUP($A24,HIST!$A:$C,3,FALSE) -> 46219 | M24: =IF(L24="","",TODAY()-L24) -> 11 | N24: =IF(K24="","",IF(K24>=R1,"Caliente",IF(K24<=R2,"Frio","Medio"))) -> Caliente | O24: =IF(N24="","",IF(M24>=R3,N24&" atrasado",N24&" reciente")) -> Caliente atrasado
A25: 23 | B25: =+VLOOKUP($A25,'CG20'!$A$364:$B$440,2,FALSE) -> 1 | C25: =+VLOOKUP($A25,'CG20'!$A$436:$B$500,2,FALSE) -> 19 | D25: =+B25*0.6/20+C25*0.4/20 -> 0.41 | E25: =+VLOOKUP($A25,'CG50'!$A$364:$B$440,2,FALSE) -> 5 | F25: =+VLOOKUP($A25,'CG50'!$A$436:$B$500,2,FALSE) -> 45 | G25: =+E25*0.6/50+F25*0.4/50 -> 0.42 | H25: =+VLOOKUP($A25,'CG100'!$A$364:$B$440,2,FALSE) -> 8 | I25: =+VLOOKUP($A25,'CG100'!$A$436:$B$500,2,FALSE) -> 92 | J25: =+H25*0.6/100+I25*0.4/100 -> 0.416 | K25: =+VLOOKUP(A25,HIST!$A:$C,2,FALSE) -> 992 | L25: =+VLOOKUP($A25,HIST!$A:$C,3,FALSE) -> 46225 | M25: =IF(L25="","",TODAY()-L25) -> 5 | N25: =IF(K25="","",IF(K25>=R1,"Caliente",IF(K25<=R2,"Frio","Medio"))) -> Medio | O25: =IF(N25="","",IF(M25>=R3,N25&" atrasado",N25&" reciente")) -> Medio reciente
A26: 24 | B26: =+VLOOKUP($A26,'CG20'!$A$364:$B$440,2,FALSE) -> 2 | C26: =+VLOOKUP($A26,'CG20'!$A$436:$B$500,2,FALSE) -> 18 | D26: =+B26*0.6/20+C26*0.4/20 -> 0.42 | E26: =+VLOOKUP($A26,'CG50'!$A$364:$B$440,2,FALSE) -> 6 | F26: =+VLOOKUP($A26,'CG50'!$A$436:$B$500,2,FALSE) -> 44 | G26: =+E26*0.6/50+F26*0.4/50 -> 0.424 | H26: =+VLOOKUP($A26,'CG100'!$A$364:$B$440,2,FALSE) -> 9 | I26: =+VLOOKUP($A26,'CG100'!$A$436:$B$500,2,FALSE) -> 91 | J26: =+H26*0.6/100+I26*0.4/100 -> 0.418 | K26: =+VLOOKUP(A26,HIST!$A:$C,2,FALSE) -> 1185 | L26: =+VLOOKUP($A26,HIST!$A:$C,3,FALSE) -> 46225 | M26: =IF(L26="","",TODAY()-L26) -> 5 | N26: =IF(K26="","",IF(K26>=R1,"Caliente",IF(K26<=R2,"Frio","Medio"))) -> Caliente | O26: =IF(N26="","",IF(M26>=R3,N26&" atrasado",N26&" reciente")) -> Caliente reciente
A27: 25 | B27: =+VLOOKUP($A27,'CG20'!$A$364:$B$440,2,FALSE) -> 1 | C27: =+VLOOKUP($A27,'CG20'!$A$436:$B$500,2,FALSE) -> 19 | D27: =+B27*0.6/20+C27*0.4/20 -> 0.41 | E27: =+VLOOKUP($A27,'CG50'!$A$364:$B$440,2,FALSE) -> 4 | F27: =+VLOOKUP($A27,'CG50'!$A$436:$B$500,2,FALSE) -> 46 | G27: =+E27*0.6/50+F27*0.4/50 -> 0.416 | H27: =+VLOOKUP($A27,'CG100'!$A$364:$B$440,2,FALSE) -> 11 | I27: =+VLOOKUP($A27,'CG100'!$A$436:$B$500,2,FALSE) -> 89 | J27: =+H27*0.6/100+I27*0.4/100 -> 0.422 | K27: =+VLOOKUP(A27,HIST!$A:$C,2,FALSE) -> 987 | L27: =+VLOOKUP($A27,HIST!$A:$C,3,FALSE) -> 46222 | M27: =IF(L27="","",TODAY()-L27) -> 8 | N27: =IF(K27="","",IF(K27>=R1,"Caliente",IF(K27<=R2,"Frio","Medio"))) -> Frio | O27: =IF(N27="","",IF(M27>=R3,N27&" atrasado",N27&" reciente")) -> Frio reciente
A28: 26 | B28: =+VLOOKUP($A28,'CG20'!$A$364:$B$440,2,FALSE) -> 5 | C28: =+VLOOKUP($A28,'CG20'!$A$436:$B$500,2,FALSE) -> 15 | D28: =+B28*0.6/20+C28*0.4/20 -> 0.45 | E28: =+VLOOKUP($A28,'CG50'!$A$364:$B$440,2,FALSE) -> 9 | F28: =+VLOOKUP($A28,'CG50'!$A$436:$B$500,2,FALSE) -> 41 | G28: =+E28*0.6/50+F28*0.4/50 -> 0.436 | H28: =+VLOOKUP($A28,'CG100'!$A$364:$B$440,2,FALSE) -> 14 | I28: =+VLOOKUP($A28,'CG100'!$A$436:$B$500,2,FALSE) -> 86 | J28: =+H28*0.6/100+I28*0.4/100 -> 0.428 | K28: =+VLOOKUP(A28,HIST!$A:$C,2,FALSE) -> 982 | L28: =+VLOOKUP($A28,HIST!$A:$C,3,FALSE) -> 46211 | M28: =IF(L28="","",TODAY()-L28) -> 19 | N28: =IF(K28="","",IF(K28>=R1,"Caliente",IF(K28<=R2,"Frio","Medio"))) -> Frio | O28: =IF(N28="","",IF(M28>=R3,N28&" atrasado",N28&" reciente")) -> Frio atrasado
A29: 27 | B29: =+VLOOKUP($A29,'CG20'!$A$364:$B$440,2,FALSE) -> 7 | C29: =+VLOOKUP($A29,'CG20'!$A$436:$B$500,2,FALSE) -> 13 | D29: =+B29*0.6/20+C29*0.4/20 -> 0.47 | E29: =+VLOOKUP($A29,'CG50'!$A$364:$B$440,2,FALSE) -> 10 | F29: =+VLOOKUP($A29,'CG50'!$A$436:$B$500,2,FALSE) -> 40 | G29: =+E29*0.6/50+F29*0.4/50 -> 0.44 | H29: =+VLOOKUP($A29,'CG100'!$A$364:$B$440,2,FALSE) -> 16 | I29: =+VLOOKUP($A29,'CG100'!$A$436:$B$500,2,FALSE) -> 84 | J29: =+H29*0.6/100+I29*0.4/100 -> 0.432 | K29: =+VLOOKUP(A29,HIST!$A:$C,2,FALSE) -> 980 | L29: =+VLOOKUP($A29,HIST!$A:$C,3,FALSE) -> 46222 | M29: =IF(L29="","",TODAY()-L29) -> 8 | N29: =IF(K29="","",IF(K29>=R1,"Caliente",IF(K29<=R2,"Frio","Medio"))) -> Frio | O29: =IF(N29="","",IF(M29>=R3,N29&" atrasado",N29&" reciente")) -> Frio reciente
A30: 28 | B30: =+VLOOKUP($A30,'CG20'!$A$364:$B$440,2,FALSE) -> 6 | C30: =+VLOOKUP($A30,'CG20'!$A$436:$B$500,2,FALSE) -> 14 | D30: =+B30*0.6/20+C30*0.4/20 -> 0.46 | E30: =+VLOOKUP($A30,'CG50'!$A$364:$B$440,2,FALSE) -> 7 | F30: =+VLOOKUP($A30,'CG50'!$A$436:$B$500,2,FALSE) -> 43 | G30: =+E30*0.6/50+F30*0.4/50 -> 0.428 | H30: =+VLOOKUP($A30,'CG100'!$A$364:$B$440,2,FALSE) -> 14 | I30: =+VLOOKUP($A30,'CG100'!$A$436:$B$500,2,FALSE) -> 86 | J30: =+H30*0.6/100+I30*0.4/100 -> 0.428 | K30: =+VLOOKUP(A30,HIST!$A:$C,2,FALSE) -> 1095 | L30: =+VLOOKUP($A30,HIST!$A:$C,3,FALSE) -> 46222 | M30: =IF(L30="","",TODAY()-L30) -> 8 | N30: =IF(K30="","",IF(K30>=R1,"Caliente",IF(K30<=R2,"Frio","Medio"))) -> Caliente | O30: =IF(N30="","",IF(M30>=R3,N30&" atrasado",N30&" reciente")) -> Caliente reciente
A31: 29 | B31: =+VLOOKUP($A31,'CG20'!$A$364:$B$440,2,FALSE) -> 3 | C31: =+VLOOKUP($A31,'CG20'!$A$436:$B$500,2,FALSE) -> 17 | D31: =+B31*0.6/20+C31*0.4/20 -> 0.43 | E31: =+VLOOKUP($A31,'CG50'!$A$364:$B$440,2,FALSE) -> 4 | F31: =+VLOOKUP($A31,'CG50'!$A$436:$B$500,2,FALSE) -> 46 | G31: =+E31*0.6/50+F31*0.4/50 -> 0.416 | H31: =+VLOOKUP($A31,'CG100'!$A$364:$B$440,2,FALSE) -> 14 | I31: =+VLOOKUP($A31,'CG100'!$A$436:$B$500,2,FALSE) -> 86 | J31: =+H31*0.6/100+I31*0.4/100 -> 0.428 | K31: =+VLOOKUP(A31,HIST!$A:$C,2,FALSE) -> 1062 | L31: =+VLOOKUP($A31,HIST!$A:$C,3,FALSE) -> 46222 | M31: =IF(L31="","",TODAY()-L31) -> 8 | N31: =IF(K31="","",IF(K31>=R1,"Caliente",IF(K31<=R2,"Frio","Medio"))) -> Medio | O31: =IF(N31="","",IF(M31>=R3,N31&" atrasado",N31&" reciente")) -> Medio reciente
A32: 30 | B32: =+VLOOKUP($A32,'CG20'!$A$364:$B$440,2,FALSE) -> 4 | C32: =+VLOOKUP($A32,'CG20'!$A$436:$B$500,2,FALSE) -> 16 | D32: =+B32*0.6/20+C32*0.4/20 -> 0.44 | E32: =+VLOOKUP($A32,'CG50'!$A$364:$B$440,2,FALSE) -> 9 | F32: =+VLOOKUP($A32,'CG50'!$A$436:$B$500,2,FALSE) -> 41 | G32: =+E32*0.6/50+F32*0.4/50 -> 0.436 | H32: =+VLOOKUP($A32,'CG100'!$A$364:$B$440,2,FALSE) -> 13 | I32: =+VLOOKUP($A32,'CG100'!$A$436:$B$500,2,FALSE) -> 87 | J32: =+H32*0.6/100+I32*0.4/100 -> 0.426 | K32: =+VLOOKUP(A32,HIST!$A:$C,2,FALSE) -> 1009 | L32: =+VLOOKUP($A32,HIST!$A:$C,3,FALSE) -> 46225 | M32: =IF(L32="","",TODAY()-L32) -> 5 | N32: =IF(K32="","",IF(K32>=R1,"Caliente",IF(K32<=R2,"Frio","Medio"))) -> Medio | O32: =IF(N32="","",IF(M32>=R3,N32&" atrasado",N32&" reciente")) -> Medio reciente
A33: 31 | B33: =+VLOOKUP($A33,'CG20'!$A$364:$B$440,2,FALSE) -> 3 | C33: =+VLOOKUP($A33,'CG20'!$A$436:$B$500,2,FALSE) -> 17 | D33: =+B33*0.6/20+C33*0.4/20 -> 0.43 | E33: =+VLOOKUP($A33,'CG50'!$A$364:$B$440,2,FALSE) -> 5 | F33: =+VLOOKUP($A33,'CG50'!$A$436:$B$500,2,FALSE) -> 45 | G33: =+E33*0.6/50+F33*0.4/50 -> 0.42 | H33: =+VLOOKUP($A33,'CG100'!$A$364:$B$440,2,FALSE) -> 12 | I33: =+VLOOKUP($A33,'CG100'!$A$436:$B$500,2,FALSE) -> 88 | J33: =+H33*0.6/100+I33*0.4/100 -> 0.424 | K33: =+VLOOKUP(A33,HIST!$A:$C,2,FALSE) -> 1093 | L33: =+VLOOKUP($A33,HIST!$A:$C,3,FALSE) -> 46225 | M33: =IF(L33="","",TODAY()-L33) -> 5 | N33: =IF(K33="","",IF(K33>=R1,"Caliente",IF(K33<=R2,"Frio","Medio"))) -> Medio | O33: =IF(N33="","",IF(M33>=R3,N33&" atrasado",N33&" reciente")) -> Medio reciente
A34: 32 | B34: =+VLOOKUP($A34,'CG20'!$A$364:$B$440,2,FALSE) -> 6 | C34: =+VLOOKUP($A34,'CG20'!$A$436:$B$500,2,FALSE) -> 14 | D34: =+B34*0.6/20+C34*0.4/20 -> 0.46 | E34: =+VLOOKUP($A34,'CG50'!$A$364:$B$440,2,FALSE) -> 8 | F34: =+VLOOKUP($A34,'CG50'!$A$436:$B$500,2,FALSE) -> 42 | G34: =+E34*0.6/50+F34*0.4/50 -> 0.432 | H34: =+VLOOKUP($A34,'CG100'!$A$364:$B$440,2,FALSE) -> 17 | I34: =+VLOOKUP($A34,'CG100'!$A$436:$B$500,2,FALSE) -> 83 | J34: =+H34*0.6/100+I34*0.4/100 -> 0.434 | K34: =+VLOOKUP(A34,HIST!$A:$C,2,FALSE) -> 979 | L34: =+VLOOKUP($A34,HIST!$A:$C,3,FALSE) -> 46222 | M34: =IF(L34="","",TODAY()-L34) -> 8 | N34: =IF(K34="","",IF(K34>=R1,"Caliente",IF(K34<=R2,"Frio","Medio"))) -> Frio | O34: =IF(N34="","",IF(M34>=R3,N34&" atrasado",N34&" reciente")) -> Frio reciente
A35: 33 | B35: =+VLOOKUP($A35,'CG20'!$A$364:$B$440,2,FALSE) -> 2 | C35: =+VLOOKUP($A35,'CG20'!$A$436:$B$500,2,FALSE) -> 18 | D35: =+B35*0.6/20+C35*0.4/20 -> 0.42 | E35: =+VLOOKUP($A35,'CG50'!$A$364:$B$440,2,FALSE) -> 7 | F35: =+VLOOKUP($A35,'CG50'!$A$436:$B$500,2,FALSE) -> 43 | G35: =+E35*0.6/50+F35*0.4/50 -> 0.428 | H35: =+VLOOKUP($A35,'CG100'!$A$364:$B$440,2,FALSE) -> 14 | I35: =+VLOOKUP($A35,'CG100'!$A$436:$B$500,2,FALSE) -> 86 | J35: =+H35*0.6/100+I35*0.4/100 -> 0.428 | K35: =+VLOOKUP(A35,HIST!$A:$C,2,FALSE) -> 994 | L35: =+VLOOKUP($A35,HIST!$A:$C,3,FALSE) -> 46222 | M35: =IF(L35="","",TODAY()-L35) -> 8 | N35: =IF(K35="","",IF(K35>=R1,"Caliente",IF(K35<=R2,"Frio","Medio"))) -> Medio | O35: =IF(N35="","",IF(M35>=R3,N35&" atrasado",N35&" reciente")) -> Medio reciente
A36: 34 | B36: =+VLOOKUP($A36,'CG20'!$A$364:$B$440,2,FALSE) -> 1 | C36: =+VLOOKUP($A36,'CG20'!$A$436:$B$500,2,FALSE) -> 19 | D36: =+B36*0.6/20+C36*0.4/20 -> 0.41 | E36: =+VLOOKUP($A36,'CG50'!$A$364:$B$440,2,FALSE) -> 6 | F36: =+VLOOKUP($A36,'CG50'!$A$436:$B$500,2,FALSE) -> 44 | G36: =+E36*0.6/50+F36*0.4/50 -> 0.424 | H36: =+VLOOKUP($A36,'CG100'!$A$364:$B$440,2,FALSE) -> 14 | I36: =+VLOOKUP($A36,'CG100'!$A$436:$B$500,2,FALSE) -> 86 | J36: =+H36*0.6/100+I36*0.4/100 -> 0.428 | K36: =+VLOOKUP(A36,HIST!$A:$C,2,FALSE) -> 1092 | L36: =+VLOOKUP($A36,HIST!$A:$C,3,FALSE) -> 46225 | M36: =IF(L36="","",TODAY()-L36) -> 5 | N36: =IF(K36="","",IF(K36>=R1,"Caliente",IF(K36<=R2,"Frio","Medio"))) -> Medio | O36: =IF(N36="","",IF(M36>=R3,N36&" atrasado",N36&" reciente")) -> Medio reciente
A37: 35 | B37: =+VLOOKUP($A37,'CG20'!$A$364:$B$440,2,FALSE) -> 1 | C37: =+VLOOKUP($A37,'CG20'!$A$436:$B$500,2,FALSE) -> 19 | D37: =+B37*0.6/20+C37*0.4/20 -> 0.41 | E37: =+VLOOKUP($A37,'CG50'!$A$364:$B$440,2,FALSE) -> 3 | F37: =+VLOOKUP($A37,'CG50'!$A$436:$B$500,2,FALSE) -> 47 | G37: =+E37*0.6/50+F37*0.4/50 -> 0.412 | H37: =+VLOOKUP($A37,'CG100'!$A$364:$B$440,2,FALSE) -> 7 | I37: =+VLOOKUP($A37,'CG100'!$A$436:$B$500,2,FALSE) -> 93 | J37: =+H37*0.6/100+I37*0.4/100 -> 0.414 | K37: =+VLOOKUP(A37,HIST!$A:$C,2,FALSE) -> 1106 | L37: =+VLOOKUP($A37,HIST!$A:$C,3,FALSE) -> 46204 | M37: =IF(L37="","",TODAY()-L37) -> 26 | N37: =IF(K37="","",IF(K37>=R1,"Caliente",IF(K37<=R2,"Frio","Medio"))) -> Caliente | O37: =IF(N37="","",IF(M37>=R3,N37&" atrasado",N37&" reciente")) -> Caliente atrasado
A38: 36 | B38: =+VLOOKUP($A38,'CG20'!$A$364:$B$440,2,FALSE) -> 2 | C38: =+VLOOKUP($A38,'CG20'!$A$436:$B$500,2,FALSE) -> 18 | D38: =+B38*0.6/20+C38*0.4/20 -> 0.42 | E38: =+VLOOKUP($A38,'CG50'!$A$364:$B$440,2,FALSE) -> 4 | F38: =+VLOOKUP($A38,'CG50'!$A$436:$B$500,2,FALSE) -> 46 | G38: =+E38*0.6/50+F38*0.4/50 -> 0.416 | H38: =+VLOOKUP($A38,'CG100'!$A$364:$B$440,2,FALSE) -> 10 | I38: =+VLOOKUP($A38,'CG100'!$A$436:$B$500,2,FALSE) -> 90 | J38: =+H38*0.6/100+I38*0.4/100 -> 0.42 | K38: =+VLOOKUP(A38,HIST!$A:$C,2,FALSE) -> 1145 | L38: =+VLOOKUP($A38,HIST!$A:$C,3,FALSE) -> 46225 | M38: =IF(L38="","",TODAY()-L38) -> 5 | N38: =IF(K38="","",IF(K38>=R1,"Caliente",IF(K38<=R2,"Frio","Medio"))) -> Caliente | O38: =IF(N38="","",IF(M38>=R3,N38&" atrasado",N38&" reciente")) -> Caliente reciente
A39: 37 | B39: =+VLOOKUP($A39,'CG20'!$A$364:$B$440,2,FALSE) -> 4 | C39: =+VLOOKUP($A39,'CG20'!$A$436:$B$500,2,FALSE) -> 16 | D39: =+B39*0.6/20+C39*0.4/20 -> 0.44 | E39: =+VLOOKUP($A39,'CG50'!$A$364:$B$440,2,FALSE) -> 9 | F39: =+VLOOKUP($A39,'CG50'!$A$436:$B$500,2,FALSE) -> 41 | G39: =+E39*0.6/50+F39*0.4/50 -> 0.436 | H39: =+VLOOKUP($A39,'CG100'!$A$364:$B$440,2,FALSE) -> 15 | I39: =+VLOOKUP($A39,'CG100'!$A$436:$B$500,2,FALSE) -> 85 | J39: =+H39*0.6/100+I39*0.4/100 -> 0.43 | K39: =+VLOOKUP(A39,HIST!$A:$C,2,FALSE) -> 1205 | L39: =+VLOOKUP($A39,HIST!$A:$C,3,FALSE) -> 46219 | M39: =IF(L39="","",TODAY()-L39) -> 11 | N39: =IF(K39="","",IF(K39>=R1,"Caliente",IF(K39<=R2,"Frio","Medio"))) -> Caliente | O39: =IF(N39="","",IF(M39>=R3,N39&" atrasado",N39&" reciente")) -> Caliente atrasado
A40: 38 | B40: =+VLOOKUP($A40,'CG20'!$A$364:$B$440,2,FALSE) -> 2 | C40: =+VLOOKUP($A40,'CG20'!$A$436:$B$500,2,FALSE) -> 18 | D40: =+B40*0.6/20+C40*0.4/20 -> 0.42 | E40: =+VLOOKUP($A40,'CG50'!$A$364:$B$440,2,FALSE) -> 5 | F40: =+VLOOKUP($A40,'CG50'!$A$436:$B$500,2,FALSE) -> 45 | G40: =+E40*0.6/50+F40*0.4/50 -> 0.42 | H40: =+VLOOKUP($A40,'CG100'!$A$364:$B$440,2,FALSE) -> 11 | I40: =+VLOOKUP($A40,'CG100'!$A$436:$B$500,2,FALSE) -> 89 | J40: =+H40*0.6/100+I40*0.4/100 -> 0.422 | K40: =+VLOOKUP(A40,HIST!$A:$C,2,FALSE) -> 982 | L40: =+VLOOKUP($A40,HIST!$A:$C,3,FALSE) -> 46225 | M40: =IF(L40="","",TODAY()-L40) -> 5 | N40: =IF(K40="","",IF(K40>=R1,"Caliente",IF(K40<=R2,"Frio","Medio"))) -> Frio | O40: =IF(N40="","",IF(M40>=R3,N40&" atrasado",N40&" reciente")) -> Frio reciente
...
